bash: get_ip.sh: No such file or directory
Traceback (most recent call last):
  File "api.py", line 78, in <module>
    ip_vm = subprocess.check_output("bash get_ip.sh", shell=True).rstrip();
  File "/usr/lib/python2.7/subprocess.py", line 223, in check_output
    raise CalledProcessError(retcode, cmd, output=output)
subprocess.CalledProcessError: Command 'bash get_ip.sh' returned non-zero exit status 127
bash: get_ip.sh: No such file or directory
Traceback (most recent call last):
  File "api.py", line 78, in <module>
    ip_vm = subprocess.check_output("bash get_ip.sh", shell=True).rstrip();
  File "/usr/lib/python2.7/subprocess.py", line 223, in check_output
    raise CalledProcessError(retcode, cmd, output=output)
subprocess.CalledProcessError: Command 'bash get_ip.sh' returned non-zero exit status 127
bash: get_ip.sh: No such file or directory
Traceback (most recent call last):
  File "api.py", line 78, in <module>
    ip_vm = subprocess.check_output("bash get_ip.sh", shell=True).rstrip();
  File "/usr/lib/python2.7/subprocess.py", line 223, in check_output
    raise CalledProcessError(retcode, cmd, output=output)
subprocess.CalledProcessError: Command 'bash get_ip.sh' returned non-zero exit status 127
bash: get_ip.sh: No such file or directory
Traceback (most recent call last):
  File "api.py", line 78, in <module>
    ip_vm = subprocess.check_output("bash get_ip.sh", shell=True).rstrip();
  File "/usr/lib/python2.7/subprocess.py", line 223, in check_output
    raise CalledProcessError(retcode, cmd, output=output)
subprocess.CalledProcessError: Command 'bash get_ip.sh' returned non-zero exit status 127
bash: get_ip.sh: No such file or directory
Traceback (most recent call last):
  File "api.py", line 78, in <module>
    ip_vm = subprocess.check_output("bash get_ip.sh", shell=True).rstrip();
  File "/usr/lib/python2.7/subprocess.py", line 223, in check_output
    raise CalledProcessError(retcode, cmd, output=output)
subprocess.CalledProcessError: Command 'bash get_ip.sh' returned non-zero exit status 127
132.199.120.10
[33m * Tip: There are .env or .flaskenv files present. Do "pip install python-dotenv" to use them.[0m
 * Serving Flask app "api" (lazy loading)
 * Environment: production
[31m   WARNING: This is a development server. Do not use it in a production deployment.[0m
[2m   Use a production WSGI server instead.[0m
 * Debug mode: off
 * Running on http://132.199.120.10:9090/ (Press CTRL+C to quit)
80.209.221.103 - - [24/Mar/2021 13:59:15] "[33mGET / HTTP/1.1[0m" 404 -
Stopping kibana        ... 
Stopping dsiem         ... 
Stopping elasticsearch ... 
Stopping digital_twin  ... 
Stopping filebeat      ... 
Stopping filebeat-es   ... 
Stopping logstash      ... 
[2A[2KStopping filebeat-es   ... [32mdone[0m[2B[1A[2KStopping logstash      ... [32mdone[0m[1B[6A[2KStopping dsiem         ... [32mdone[0m[6B[4A[2KStopping digital_twin  ... [32mdone[0m[4B[7A[2KStopping kibana        ... [32mdone[0m[7B[3A[2KStopping filebeat      ... [32mdone[0m[3B[5A[2KStopping elasticsearch ... [32mdone[0m[5B80.209.221.103 - - [24/Mar/2021 13:59:45] "[37mGET /docker_stop HTTP/1.1[0m" 200 -
80.209.221.103 - - [24/Mar/2021 14:07:27] "[33mGET /docker_start HTTP/1.1[0m" 404 -
80.209.221.103 - - [24/Mar/2021 14:07:33] "[37mGET /docker_restart HTTP/1.1[0m" 200 -
132.199.120.10
[33m * Tip: There are .env or .flaskenv files present. Do "pip install python-dotenv" to use them.[0m
 * Serving Flask app "api" (lazy loading)
 * Environment: production
[31m   WARNING: This is a development server. Do not use it in a production deployment.[0m
[2m   Use a production WSGI server instead.[0m
 * Debug mode: off
 * Running on http://132.199.120.10:9090/ (Press CTRL+C to quit)
132.199.120.10
[33m * Tip: There are .env or .flaskenv files present. Do "pip install python-dotenv" to use them.[0m
 * Serving Flask app "api" (lazy loading)
 * Environment: production
[31m   WARNING: This is a development server. Do not use it in a production deployment.[0m
[2m   Use a production WSGI server instead.[0m
 * Debug mode: off
 * Running on http://132.199.120.10:9090/ (Press CTRL+C to quit)
80.209.221.103 - - [24/Mar/2021 14:11:15] "[33mGET / HTTP/1.1[0m" 404 -
132.199.120.10
[33m * Tip: There are .env or .flaskenv files present. Do "pip install python-dotenv" to use them.[0m
 * Serving Flask app "api" (lazy loading)
 * Environment: production
[31m   WARNING: This is a development server. Do not use it in a production deployment.[0m
[2m   Use a production WSGI server instead.[0m
 * Debug mode: off
 * Running on http://132.199.120.10:9090/ (Press CTRL+C to quit)
80.209.221.103 - - [24/Mar/2021 14:13:45] "[33mGET / HTTP/1.1[0m" 404 -
[33m * Tip: There are .env or .flaskenv files present. Do "pip install python-dotenv" to use them.[0m
 * Serving Flask app "api" (lazy loading)
 * Environment: production
[31m   WARNING: This is a development server. Do not use it in a production deployment.[0m
[2m   Use a production WSGI server instead.[0m
 * Debug mode: off
Traceback (most recent call last):
  File "api.py", line 80, in <module>
    app.run(port=9090, host=ip_vm)
  File "/usr/local/lib/python2.7/dist-packages/flask/app.py", line 990, in run
    run_simple(host, port, self, **options)
  File "/usr/local/lib/python2.7/dist-packages/werkzeug/serving.py", line 1052, in run_simple
    inner()
  File "/usr/local/lib/python2.7/dist-packages/werkzeug/serving.py", line 1005, in inner
    fd=fd,
  File "/usr/local/lib/python2.7/dist-packages/werkzeug/serving.py", line 848, in make_server
    host, port, app, request_handler, passthrough_errors, ssl_context, fd=fd
  File "/usr/local/lib/python2.7/dist-packages/werkzeug/serving.py", line 740, in __init__
    HTTPServer.__init__(self, server_address, handler)
  File "/usr/lib/python2.7/SocketServer.py", line 420, in __init__
    self.server_bind()
  File "/usr/lib/python2.7/BaseHTTPServer.py", line 108, in server_bind
    SocketServer.TCPServer.server_bind(self)
  File "/usr/lib/python2.7/SocketServer.py", line 434, in server_bind
    self.socket.bind(self.server_address)
  File "/usr/lib/python2.7/socket.py", line 228, in meth
    return getattr(self._sock,name)(*args)
socket.error: [Errno 98] Address already in use
[33m * Tip: There are .env or .flaskenv files present. Do "pip install python-dotenv" to use them.[0m
 * Serving Flask app "api" (lazy loading)
 * Environment: production
[31m   WARNING: This is a development server. Do not use it in a production deployment.[0m
[2m   Use a production WSGI server instead.[0m
 * Debug mode: off
Traceback (most recent call last):
  File "api.py", line 80, in <module>
    app.run(port=9090, host=ip_vm)
  File "/usr/local/lib/python2.7/dist-packages/flask/app.py", line 990, in run
    run_simple(host, port, self, **options)
  File "/usr/local/lib/python2.7/dist-packages/werkzeug/serving.py", line 1052, in run_simple
    inner()
  File "/usr/local/lib/python2.7/dist-packages/werkzeug/serving.py", line 1005, in inner
    fd=fd,
  File "/usr/local/lib/python2.7/dist-packages/werkzeug/serving.py", line 848, in make_server
    host, port, app, request_handler, passthrough_errors, ssl_context, fd=fd
  File "/usr/local/lib/python2.7/dist-packages/werkzeug/serving.py", line 740, in __init__
    HTTPServer.__init__(self, server_address, handler)
  File "/usr/lib/python2.7/SocketServer.py", line 420, in __init__
    self.server_bind()
  File "/usr/lib/python2.7/BaseHTTPServer.py", line 108, in server_bind
    SocketServer.TCPServer.server_bind(self)
  File "/usr/lib/python2.7/SocketServer.py", line 434, in server_bind
    self.socket.bind(self.server_address)
  File "/usr/lib/python2.7/socket.py", line 228, in meth
    return getattr(self._sock,name)(*args)
socket.error: [Errno 98] Address already in use
